[2025-04-07T14:52:27.493+0000] {taskinstance.py:1956} INFO - Dependencies all met for dep_context=non-requeueable deps ti=<TaskInstance: dlt_citibike_pipeline.run_citibike_pipeline manual__2025-04-07T14:52:08+00:00 [queued]>
[2025-04-07T14:52:27.505+0000] {taskinstance.py:1956} INFO - Dependencies all met for dep_context=requeueable deps ti=<TaskInstance: dlt_citibike_pipeline.run_citibike_pipeline manual__2025-04-07T14:52:08+00:00 [queued]>
[2025-04-07T14:52:27.505+0000] {taskinstance.py:2170} INFO - Starting attempt 1 of 2
[2025-04-07T14:52:27.529+0000] {taskinstance.py:2191} INFO - Executing <Task(PythonOperator): run_citibike_pipeline> on 2025-04-07 14:52:08+00:00
[2025-04-07T14:52:27.539+0000] {standard_task_runner.py:60} INFO - Started process 106 to run task
[2025-04-07T14:52:27.545+0000] {standard_task_runner.py:87} INFO - Running: ['***', 'tasks', 'run', 'dlt_citibike_pipeline', 'run_citibike_pipeline', 'manual__2025-04-07T14:52:08+00:00', '--job-id', '7', '--raw', '--subdir', 'DAGS_FOLDER/dlt_ingestion_dag.py', '--cfg-path', '/tmp/tmpa9vyomnx']
[2025-04-07T14:52:27.547+0000] {standard_task_runner.py:88} INFO - Job 7: Subtask run_citibike_pipeline
[2025-04-07T14:52:27.608+0000] {task_command.py:423} INFO - Running <TaskInstance: dlt_citibike_pipeline.run_citibike_pipeline manual__2025-04-07T14:52:08+00:00 [running]> on host d53833d9bb94
[2025-04-07T14:52:27.707+0000] {taskinstance.py:2480} INFO - Exporting env vars: AIRFLOW_CTX_DAG_OWNER='***' AIRFLOW_CTX_DAG_ID='dlt_citibike_pipeline' AIRFLOW_CTX_TASK_ID='run_citibike_pipeline' AIRFLOW_CTX_EXECUTION_DATE='2025-04-07T14:52:08+00:00' AIRFLOW_CTX_TRY_NUMBER='1' AIRFLOW_CTX_DAG_RUN_ID='manual__2025-04-07T14:52:08+00:00'
[2025-04-07T14:52:27.711+0000] {taskinstance.py:2698} ERROR - Task failed with exception
Traceback (most recent call last):
  File "/home/airflow/.local/lib/python3.10/site-packages/airflow/models/taskinstance.py", line 433, in _execute_task
    result = execute_callable(context=context, **execute_callable_kwargs)
  File "/home/airflow/.local/lib/python3.10/site-packages/airflow/operators/python.py", line 199, in execute
    return_value = self.execute_callable()
  File "/home/airflow/.local/lib/python3.10/site-packages/airflow/operators/python.py", line 216, in execute_callable
    return self.python_callable(*self.op_args, **self.op_kwargs)
  File "/opt/airflow/dags/dlt_ingestion_dag.py", line 24, in run_pipeline
    import dlt_citibike
ModuleNotFoundError: No module named 'dlt_citibike'
[2025-04-07T14:52:27.722+0000] {taskinstance.py:1138} INFO - Marking task as UP_FOR_RETRY. dag_id=dlt_citibike_pipeline, task_id=run_citibike_pipeline, execution_date=20250407T145208, start_date=20250407T145227, end_date=20250407T145227
[2025-04-07T14:52:27.739+0000] {standard_task_runner.py:107} ERROR - Failed to execute job 7 for task run_citibike_pipeline (No module named 'dlt_citibike'; 106)
[2025-04-07T14:52:27.756+0000] {local_task_job_runner.py:234} INFO - Task exited with return code 1
[2025-04-07T14:52:27.782+0000] {taskinstance.py:3280} INFO - 0 downstream tasks scheduled from follow-on schedule check
