[2025-04-07T16:27:58.143+0000] {scheduler_job_runner.py:1586} WARNING - Marking task instance <TaskInstance: dlt_citibike_pipeline.upload_new_data_05 scheduled__2025-02-01T00:00:00+00:00 [queued]> stuck in queued as failed. If the task instance has available retries, it will be retried.
[2025-04-07T16:27:58.248+0000] {scheduler_job_runner.py:781} ERROR - Executor reports task instance <TaskInstance: dlt_citibike_pipeline.upload_new_data_05 scheduled__2025-02-01T00:00:00+00:00 [queued]> finished (failed) although the task says it's queued. (Info: None) Was the task killed externally?
