[2025-04-06T16:22:08.352+0000] {local_task_job_runner.py:123} INFO - ::group::Pre task execution logs
[2025-04-06T16:22:08.421+0000] {taskinstance.py:2614} INFO - Dependencies all met for dep_context=non-requeueable deps ti=<TaskInstance: dlt_ingestion_dag.run_dlt_ingestion manual__2025-04-06T16:03:01+00:00 [queued]>
[2025-04-06T16:22:08.456+0000] {taskinstance.py:2614} INFO - Dependencies all met for dep_context=requeueable deps ti=<TaskInstance: dlt_ingestion_dag.run_dlt_ingestion manual__2025-04-06T16:03:01+00:00 [queued]>
[2025-04-06T16:22:08.457+0000] {taskinstance.py:2867} INFO - Starting attempt 2 of 2
[2025-04-06T16:22:08.848+0000] {taskinstance.py:2890} INFO - Executing <Task(PythonOperator): run_dlt_ingestion> on 2025-04-06 16:03:01+00:00
[2025-04-06T16:22:08.868+0000] {warnings.py:112} WARNING - /home/***/.local/lib/python3.12/site-packages/***/task/task_runner/standard_task_runner.py:70: DeprecationWarning: This process (pid=138) is multi-threaded, use of fork() may lead to deadlocks in the child.
  pid = os.fork()

[2025-04-06T16:22:08.871+0000] {standard_task_runner.py:72} INFO - Started process 148 to run task
[2025-04-06T16:22:08.877+0000] {standard_task_runner.py:104} INFO - Running: ['***', 'tasks', 'run', 'dlt_ingestion_dag', 'run_dlt_ingestion', 'manual__2025-04-06T16:03:01+00:00', '--job-id', '16', '--raw', '--subdir', 'DAGS_FOLDER/dlt_ingestion_dag.py', '--cfg-path', '/tmp/tmpgjjj80xo']
[2025-04-06T16:22:08.879+0000] {standard_task_runner.py:105} INFO - Job 16: Subtask run_dlt_ingestion
[2025-04-06T16:22:09.088+0000] {task_command.py:467} INFO - Running <TaskInstance: dlt_ingestion_dag.run_dlt_ingestion manual__2025-04-06T16:03:01+00:00 [running]> on host 6d9252ef6c72
[2025-04-06T16:22:09.379+0000] {taskinstance.py:3134} INFO - Exporting env vars: AIRFLOW_CTX_DAG_OWNER='***' AIRFLOW_CTX_DAG_ID='dlt_ingestion_dag' AIRFLOW_CTX_TASK_ID='run_dlt_ingestion' AIRFLOW_CTX_EXECUTION_DATE='2025-04-06T16:03:01+00:00' AIRFLOW_CTX_TRY_NUMBER='2' AIRFLOW_CTX_DAG_RUN_ID='manual__2025-04-06T16:03:01+00:00'
[2025-04-06T16:22:09.387+0000] {logging_mixin.py:190} INFO - Task instance is in running state
[2025-04-06T16:22:09.389+0000] {logging_mixin.py:190} INFO -  Previous state of the Task instance: queued
[2025-04-06T16:22:09.395+0000] {logging_mixin.py:190} INFO - Current task name:run_dlt_ingestion state:running start_date:2025-04-06 16:22:08.430364+00:00
[2025-04-06T16:22:09.396+0000] {logging_mixin.py:190} INFO - Dag name:dlt_ingestion_dag and current dag run status:running
[2025-04-06T16:22:09.398+0000] {taskinstance.py:732} INFO - ::endgroup::
[2025-04-06T16:22:09.616+0000] {dlt_ingestion_dag.py:30} ERROR - Error running DLT script: Command '['python', '/opt/***/dlt_pipeline/dlt_citibike.py', '--year', '2022']' returned non-zero exit status 1.
[2025-04-06T16:22:09.617+0000] {dlt_ingestion_dag.py:31} ERROR - STDOUT: 
[2025-04-06T16:22:09.618+0000] {dlt_ingestion_dag.py:32} ERROR - STDERR: Traceback (most recent call last):
  File "/opt/***/dlt_pipeline/dlt_citibike.py", line 1, in <module>
    import dlt
ModuleNotFoundError: No module named 'dlt'

[2025-04-06T16:22:09.618+0000] {taskinstance.py:3313} ERROR - Task failed with exception
Traceback (most recent call last):
  File "/home/airflow/.local/lib/python3.12/site-packages/airflow/models/taskinstance.py", line 768, in _execute_task
    result = _execute_callable(context=context, **execute_callable_kwargs)
             ^^^^^^^^^^^^^^^^^^^^^^^^^^^^^^^^^^^^^^^^^^^^^^^^^^^^^^^^^^^^^
  File "/home/airflow/.local/lib/python3.12/site-packages/airflow/models/taskinstance.py", line 734, in _execute_callable
    return ExecutionCallableRunner(
           ^^^^^^^^^^^^^^^^^^^^^^^^
  File "/home/airflow/.local/lib/python3.12/site-packages/airflow/utils/operator_helpers.py", line 252, in run
    return self.func(*args, **kwargs)
           ^^^^^^^^^^^^^^^^^^^^^^^^^^
  File "/home/airflow/.local/lib/python3.12/site-packages/airflow/models/baseoperator.py", line 424, in wrapper
    return func(self, *args, **kwargs)
           ^^^^^^^^^^^^^^^^^^^^^^^^^^^
  File "/home/airflow/.local/lib/python3.12/site-packages/airflow/operators/python.py", line 238, in execute
    return_value = self.execute_callable()
                   ^^^^^^^^^^^^^^^^^^^^^^^
  File "/home/airflow/.local/lib/python3.12/site-packages/airflow/operators/python.py", line 256, in execute_callable
    return runner.run(*self.op_args, **self.op_kwargs)
           ^^^^^^^^^^^^^^^^^^^^^^^^^^^^^^^^^^^^^^^^^^^
  File "/home/airflow/.local/lib/python3.12/site-packages/airflow/utils/operator_helpers.py", line 252, in run
    return self.func(*args, **kwargs)
           ^^^^^^^^^^^^^^^^^^^^^^^^^^
  File "/opt/airflow/dags/dlt_ingestion_dag.py", line 17, in run_dlt_script
    result = subprocess.run(
             ^^^^^^^^^^^^^^^
  File "/usr/local/lib/python3.12/subprocess.py", line 573, in run
    raise CalledProcessError(retcode, process.args,
subprocess.CalledProcessError: Command '['python', '/opt/airflow/dlt_pipeline/dlt_citibike.py', '--year', '2022']' returned non-zero exit status 1.
[2025-04-06T16:22:09.730+0000] {logging_mixin.py:190} INFO - Task instance in failure state
[2025-04-06T16:22:09.745+0000] {logging_mixin.py:190} INFO - Task start:2025-04-06 16:22:08.430364+00:00 end:2025-04-06 16:22:09.729250+00:00 duration:1.298886
[2025-04-06T16:22:09.746+0000] {logging_mixin.py:190} INFO - Task:<Task(PythonOperator): run_dlt_ingestion> dag:<DAG: dlt_ingestion_dag> dagrun:<DagRun dlt_ingestion_dag @ 2025-04-06 16:03:01+00:00: manual__2025-04-06T16:03:01+00:00, state:running, queued_at: 2025-04-06 16:03:31.270356+00:00. externally triggered: True>
[2025-04-06T16:22:09.751+0000] {logging_mixin.py:190} INFO - Failure caused by Command '['python', '/opt/***/dlt_pipeline/dlt_citibike.py', '--year', '2022']' returned non-zero exit status 1.
[2025-04-06T16:22:09.758+0000] {taskinstance.py:1226} INFO - Marking task as FAILED. dag_id=dlt_ingestion_dag, task_id=run_dlt_ingestion, run_id=manual__2025-04-06T16:03:01+00:00, execution_date=20250406T160301, start_date=20250406T162208, end_date=20250406T162209
[2025-04-06T16:22:09.984+0000] {taskinstance.py:341} INFO - ::group::Post task execution logs
[2025-04-06T16:22:09.985+0000] {standard_task_runner.py:124} ERROR - Failed to execute job 16 for task run_dlt_ingestion (Command '['python', '/opt/airflow/dlt_pipeline/dlt_citibike.py', '--year', '2022']' returned non-zero exit status 1.; 148)
Traceback (most recent call last):
  File "/home/airflow/.local/lib/python3.12/site-packages/airflow/task/task_runner/standard_task_runner.py", line 117, in _start_by_fork
    ret = args.func(args, dag=self.dag)
          ^^^^^^^^^^^^^^^^^^^^^^^^^^^^^
  File "/home/airflow/.local/lib/python3.12/site-packages/airflow/cli/cli_config.py", line 49, in command
    return func(*args, **kwargs)
           ^^^^^^^^^^^^^^^^^^^^^
  File "/home/airflow/.local/lib/python3.12/site-packages/airflow/utils/cli.py", line 116, in wrapper
    return f(*args, **kwargs)
           ^^^^^^^^^^^^^^^^^^
  File "/home/airflow/.local/lib/python3.12/site-packages/airflow/cli/commands/task_command.py", line 483, in task_run
    task_return_code = _run_task_by_selected_method(args, _dag, ti)
                       ^^^^^^^^^^^^^^^^^^^^^^^^^^^^^^^^^^^^^^^^^^^^
  File "/home/airflow/.local/lib/python3.12/site-packages/airflow/cli/commands/task_command.py", line 256, in _run_task_by_selected_method
    return _run_raw_task(args, ti)
           ^^^^^^^^^^^^^^^^^^^^^^^
  File "/home/airflow/.local/lib/python3.12/site-packages/airflow/cli/commands/task_command.py", line 341, in _run_raw_task
    return ti._run_raw_task(
           ^^^^^^^^^^^^^^^^^
  File "/home/airflow/.local/lib/python3.12/site-packages/airflow/utils/session.py", line 97, in wrapper
    return func(*args, session=session, **kwargs)
           ^^^^^^^^^^^^^^^^^^^^^^^^^^^^^^^^^^^^^^
  File "/home/airflow/.local/lib/python3.12/site-packages/airflow/models/taskinstance.py", line 3006, in _run_raw_task
    return _run_raw_task(
           ^^^^^^^^^^^^^^
  File "/home/airflow/.local/lib/python3.12/site-packages/airflow/models/taskinstance.py", line 274, in _run_raw_task
    TaskInstance._execute_task_with_callbacks(
  File "/home/airflow/.local/lib/python3.12/site-packages/airflow/models/taskinstance.py", line 3161, in _execute_task_with_callbacks
    result = self._execute_task(context, task_orig)
             ^^^^^^^^^^^^^^^^^^^^^^^^^^^^^^^^^^^^^^
  File "/home/airflow/.local/lib/python3.12/site-packages/airflow/models/taskinstance.py", line 3185, in _execute_task
    return _execute_task(self, context, task_orig)
           ^^^^^^^^^^^^^^^^^^^^^^^^^^^^^^^^^^^^^^^
  File "/home/airflow/.local/lib/python3.12/site-packages/airflow/models/taskinstance.py", line 768, in _execute_task
    result = _execute_callable(context=context, **execute_callable_kwargs)
             ^^^^^^^^^^^^^^^^^^^^^^^^^^^^^^^^^^^^^^^^^^^^^^^^^^^^^^^^^^^^^
  File "/home/airflow/.local/lib/python3.12/site-packages/airflow/models/taskinstance.py", line 734, in _execute_callable
    return ExecutionCallableRunner(
           ^^^^^^^^^^^^^^^^^^^^^^^^
  File "/home/airflow/.local/lib/python3.12/site-packages/airflow/utils/operator_helpers.py", line 252, in run
    return self.func(*args, **kwargs)
           ^^^^^^^^^^^^^^^^^^^^^^^^^^
  File "/home/airflow/.local/lib/python3.12/site-packages/airflow/models/baseoperator.py", line 424, in wrapper
    return func(self, *args, **kwargs)
           ^^^^^^^^^^^^^^^^^^^^^^^^^^^
  File "/home/airflow/.local/lib/python3.12/site-packages/airflow/operators/python.py", line 238, in execute
    return_value = self.execute_callable()
                   ^^^^^^^^^^^^^^^^^^^^^^^
  File "/home/airflow/.local/lib/python3.12/site-packages/airflow/operators/python.py", line 256, in execute_callable
    return runner.run(*self.op_args, **self.op_kwargs)
           ^^^^^^^^^^^^^^^^^^^^^^^^^^^^^^^^^^^^^^^^^^^
  File "/home/airflow/.local/lib/python3.12/site-packages/airflow/utils/operator_helpers.py", line 252, in run
    return self.func(*args, **kwargs)
           ^^^^^^^^^^^^^^^^^^^^^^^^^^
  File "/opt/airflow/dags/dlt_ingestion_dag.py", line 17, in run_dlt_script
    result = subprocess.run(
             ^^^^^^^^^^^^^^^
  File "/usr/local/lib/python3.12/subprocess.py", line 573, in run
    raise CalledProcessError(retcode, process.args,
subprocess.CalledProcessError: Command '['python', '/opt/airflow/dlt_pipeline/dlt_citibike.py', '--year', '2022']' returned non-zero exit status 1.
[2025-04-06T16:22:10.043+0000] {local_task_job_runner.py:266} INFO - Task exited with return code 1
[2025-04-06T16:22:10.104+0000] {taskinstance.py:3901} INFO - 0 downstream tasks scheduled from follow-on schedule check
[2025-04-06T16:22:10.110+0000] {local_task_job_runner.py:245} INFO - ::endgroup::
