[2025-04-07T16:22:07.836+0000] {taskinstance.py:1956} INFO - Dependencies all met for dep_context=non-requeueable deps ti=<TaskInstance: dlt_citibike_pipeline.upload_new_data_07 scheduled__2025-03-01T00:00:00+00:00 [queued]>
[2025-04-07T16:22:07.847+0000] {taskinstance.py:1956} INFO - Dependencies all met for dep_context=requeueable deps ti=<TaskInstance: dlt_citibike_pipeline.upload_new_data_07 scheduled__2025-03-01T00:00:00+00:00 [queued]>
[2025-04-07T16:22:07.848+0000] {taskinstance.py:2170} INFO - Starting attempt 2 of 2
[2025-04-07T16:22:07.863+0000] {taskinstance.py:2191} INFO - Executing <Task(PythonOperator): upload_new_data_07> on 2025-03-01 00:00:00+00:00
[2025-04-07T16:22:07.871+0000] {standard_task_runner.py:60} INFO - Started process 282 to run task
[2025-04-07T16:22:07.875+0000] {standard_task_runner.py:87} INFO - Running: ['***', 'tasks', 'run', 'dlt_citibike_pipeline', 'upload_new_data_07', 'scheduled__2025-03-01T00:00:00+00:00', '--job-id', '103', '--raw', '--subdir', 'DAGS_FOLDER/dlt_ingestion_dag.py', '--cfg-path', '/tmp/tmp864g2tjp']
[2025-04-07T16:22:07.878+0000] {standard_task_runner.py:88} INFO - Job 103: Subtask upload_new_data_07
[2025-04-07T16:22:07.941+0000] {task_command.py:423} INFO - Running <TaskInstance: dlt_citibike_pipeline.upload_new_data_07 scheduled__2025-03-01T00:00:00+00:00 [running]> on host d53833d9bb94
[2025-04-07T16:22:08.049+0000] {taskinstance.py:2480} INFO - Exporting env vars: AIRFLOW_CTX_DAG_OWNER='***' AIRFLOW_CTX_DAG_ID='dlt_citibike_pipeline' AIRFLOW_CTX_TASK_ID='upload_new_data_07' AIRFLOW_CTX_EXECUTION_DATE='2025-03-01T00:00:00+00:00' AIRFLOW_CTX_TRY_NUMBER='2' AIRFLOW_CTX_DAG_RUN_ID='scheduled__2025-03-01T00:00:00+00:00'
[2025-04-07T16:22:08.052+0000] {logging_mixin.py:188} INFO - Running upload for 2025-07...
[2025-04-07T16:24:30.419+0000] {taskinstance.py:2698} ERROR - Task failed with exception
Traceback (most recent call last):
  File "/home/airflow/.local/lib/python3.10/site-packages/airflow/models/taskinstance.py", line 433, in _execute_task
    result = execute_callable(context=context, **execute_callable_kwargs)
  File "/home/airflow/.local/lib/python3.10/site-packages/airflow/operators/python.py", line 199, in execute
    return_value = self.execute_callable()
  File "/home/airflow/.local/lib/python3.10/site-packages/airflow/operators/python.py", line 216, in execute_callable
    return self.python_callable(*self.op_args, **self.op_kwargs)
  File "/opt/airflow/dags/dlt_ingestion_dag.py", line 32, in run_upload_new_data
    subprocess.run(command, check=True)
  File "/usr/local/lib/python3.10/subprocess.py", line 526, in run
    raise CalledProcessError(retcode, process.args,
subprocess.CalledProcessError: Command '['python3', '/opt/airflow/dags/upload_new_data.py', '--year', '2025']' returned non-zero exit status 1.
[2025-04-07T16:24:30.474+0000] {taskinstance.py:1138} INFO - Marking task as FAILED. dag_id=dlt_citibike_pipeline, task_id=upload_new_data_07, execution_date=20250301T000000, start_date=20250407T162207, end_date=20250407T162430
[2025-04-07T16:24:30.531+0000] {standard_task_runner.py:107} ERROR - Failed to execute job 103 for task upload_new_data_07 (Command '['python3', '/opt/airflow/dags/upload_new_data.py', '--year', '2025']' returned non-zero exit status 1.; 282)
[2025-04-07T16:24:30.602+0000] {local_task_job_runner.py:234} INFO - Task exited with return code 1
[2025-04-07T16:24:30.657+0000] {taskinstance.py:3280} INFO - 0 downstream tasks scheduled from follow-on schedule check
